Workbook

Sheet Inspection 1-40 (2)
A1: BÁO CÁO KIỂM TRA LINH KIỆN
A2: THE PARTS INSPECTION REPORT MMFDIF067.00 (16Jan2026)
L4: Date/Ngày kiểm tra: | N4: 12-MAR-2026
A5: Parts Name/Tên linh kiện: | C5: 106C | D5: Mold Name/Tên khuôn: | G5: MF00307 | K5: Department/Bộ phận: | N5: INJECTION
A6: Materia/Nguyên liệu: | C6: HPM31 | F6: HRC : | G6: 56-58 | K6: QTY/Số lượng: | N6: 2
P7: JUDGEMENT
A8: A) Calipers B) Digital micrometer C) Microscope D) Comparator E) Pin gauge F) Micrometer | P8: =IF(COUNTIF(P14:P60, "NG")>0, "REJECTED", IF(COUNTIF(P14:P60, "OK")>0, "PASSED", "")) -> PASSED
A9: A) Thước cặp B) Thước đo điện tử C) Kính hiểm vi D) Bộ căn dưỡng E) Đồng hồ đo F) Panme
A11: Specification | F11: Sample No.
A12: Point/Điểm | B12: Nominal | C12: Tol/Dung sai | E12: Tool | F12: 1 | G12: 2 | H12: 3 | I12: 4 | J12: 5 | K12: 6 | L12: 7 | M12: 8 | N12: 9 | O12: 10 | P12: Remark/Ghi chú
C13: - | D13: + | F13: Detail/Chi tiết
A14: 1 | B14: 5.1825 | C14: -0.005 | D14: 0.005 | E14: C | F14: 5.178 | G14: 5.178 | P14: =IF(COUNT(F14:O14)=0, "", IF(OR(MIN(F14:O14) < (B14+C14), MAX(F14:O14) > (B14+D14)), "NG", "OK")) -> OK
A15: 2 | B15: 1.54 | C15: -0.001 | D15: 0.001 | E15: C | F15: 1.539 | G15: 1.541 | P15: =IF(COUNT(F15:O15)=0, "", IF(OR(MIN(F15:O15) < (B15+C15), MAX(F15:O15) > (B15+D15)), "NG", "OK")) -> OK
A16: 3 | B16: 34.34 | C16: -0.005 | D16: 0.005 | E16: C | F16: 34.34 | G16: 34.337 | P16: =IF(COUNT(F16:O16)=0, "", IF(OR(MIN(F16:O16) < (B16+C16), MAX(F16:O16) > (B16+D16)), "NG", "OK")) -> OK
A17: 4 | B17: 28.03 | C17: 0 | D17: 0.005 | E17: C | F17: 28.032 | P17: =IF(COUNT(F17:O17)=0, "", IF(OR(MIN(F17:O17) < (B17+C17), MAX(F17:O17) > (B17+D17)), "NG", "OK")) -> OK
A18: 5 | B18: 19 | C18: -0.005 | D18: 0 | E18: C | F18: 18.997 | P18: =IF(COUNT(F18:O18)=0, "", IF(OR(MIN(F18:O18) < (B18+C18), MAX(F18:O18) > (B18+D18)), "NG", "OK")) -> OK
A19: 6 | B19: 0.1825 | C19: -0.005 | D19: 0.005 | E19: C | F19: 0.1838 | P19: =IF(COUNT(F19:O19)=0, "", IF(OR(MIN(F19:O19) < (B19+C19), MAX(F19:O19) > (B19+D19)), "NG", "OK")) -> OK
A20: 7 | B20: 5 | C20: -0.1 | D20: 0.1 | E20: C | F20: 5.1 | P20: =IF(COUNT(F20:O20)=0, "", IF(OR(MIN(F20:O20) < (B20+C20), MAX(F20:O20) > (B20+D20)), "NG", "OK")) -> OK
A21: 8 | B21: 33.14 | C21: 0 | D21: 0.005 | E21: C | F21: 33.142 | P21: =IF(COUNT(F21:O21)=0, "", IF(OR(MIN(F21:O21) < (B21+C21), MAX(F21:O21) > (B21+D21)), "NG", "OK")) -> OK
A22: 9 | B22: 0.03 | C22: -0.03 | D22: 0 | E22: C | F22: 0.01 | P22: =IF(COUNT(F22:O22)=0, "", IF(OR(MIN(F22:O22) < (B22+C22), MAX(F22:O22) > (B22+D22)), "NG", "OK")) -> OK
A23: 10 | B23: 0.03 | C23: -0.03 | D23: 0 | E23: C | F23: 0.01 | P23: =IF(COUNT(F23:O23)=0, "", IF(OR(MIN(F23:O23) < (B23+C23), MAX(F23:O23) > (B23+D23)), "NG", "OK")) -> OK
A24: 11 | B24: 0.54 | C24: 0 | D24: 0.005 | E24: C | F24: 0.544 | G24: 0.542 | P24: =IF(COUNT(F24:O24)=0, "", IF(OR(MIN(F24:O24) < (B24+C24), MAX(F24:O24) > (B24+D24)), "NG", "OK")) -> OK
A25: 12 | B25: 0.175 | C25: 0 | D25: 0.005 | E25: C | F25: 0.175 | G25: 0.176 | P25: =IF(COUNT(F25:O25)=0, "", IF(OR(MIN(F25:O25) < (B25+C25), MAX(F25:O25) > (B25+D25)), "NG", "OK")) -> OK
A26: 13 | B26: 0.175 | C26: 0 | D26: 0.005 | E26: C | F26: 0.176 | G26: 0.179 | P26: =IF(COUNT(F26:O26)=0, "", IF(OR(MIN(F26:O26) < (B26+C26), MAX(F26:O26) > (B26+D26)), "NG", "OK")) -> OK
A27: 14 | B27: 0.175 | C27: 0 | D27: 0.005 | E27: C | F27: 0.178 | G27: 0.175 | P27: =IF(COUNT(F27:O27)=0, "", IF(OR(MIN(F27:O27) < (B27+C27), MAX(F27:O27) > (B27+D27)), "NG", "OK")) -> OK
A28: 15 | B28: 0.175 | C28: 0 | D28: 0.005 | E28: C | F28: 0.177 | G28: 0.177 | P28: =IF(COUNT(F28:O28)=0, "", IF(OR(MIN(F28:O28) < (B28+C28), MAX(F28:O28) > (B28+D28)), "NG", "OK")) -> OK
A29: 16 | B29: 0.175 | C29: 0 | D29: 0.005 | E29: C | F29: 0.177 | G29: 0.175 | P29: =IF(COUNT(F29:O29)=0, "", IF(OR(MIN(F29:O29) < (B29+C29), MAX(F29:O29) > (B29+D29)), "NG", "OK")) -> OK
A30: 17 | B30: 0.175 | C30: 0 | D30: 0.005 | E30: C | F30: 0.177 | G30: 0.175 | P30: =IF(COUNT(F30:O30)=0, "", IF(OR(MIN(F30:O30) < (B30+C30), MAX(F30:O30) > (B30+D30)), "NG", "OK")) -> OK
A31: 18 | B31: 0.175 | C31: 0 | D31: 0.005 | E31: C | F31: 0.178 | G31: 0.175 | P31: =IF(COUNT(F31:O31)=0, "", IF(OR(MIN(F31:O31) < (B31+C31), MAX(F31:O31) > (B31+D31)), "NG", "OK")) -> OK
A32: 19 | B32: 0.175 | C32: 0 | D32: 0.005 | E32: C | F32: 0.179 | G32: 0.175 | P32: =IF(COUNT(F32:O32)=0, "", IF(OR(MIN(F32:O32) < (B32+C32), MAX(F32:O32) > (B32+D32)), "NG", "OK")) -> OK
A33: 20 | B33: 0.175 | C33: 0 | D33: 0.005 | E33: C | F33: 0.18 | G33: 0.176 | P33: =IF(COUNT(F33:O33)=0, "", IF(OR(MIN(F33:O33) < (B33+C33), MAX(F33:O33) > (B33+D33)), "NG", "OK")) -> OK
A34: 21 | B34: 0.175 | C34: 0 | D34: 0.005 | E34: C | F34: 0.176 | G34: 0.179 | P34: =IF(COUNT(F34:O34)=0, "", IF(OR(MIN(F34:O34) < (B34+C34), MAX(F34:O34) > (B34+D34)), "NG", "OK")) -> OK
A35: 22 | B35: 0.175 | C35: 0 | D35: 0.005 | E35: C | F35: 0.175 | G35: 0.179 | P35: =IF(COUNT(F35:O35)=0, "", IF(OR(MIN(F35:O35) < (B35+C35), MAX(F35:O35) > (B35+D35)), "NG", "OK")) -> OK
... A44: 31 | B44: 0.175 | C44: 0 | D44: 0.005 | E44: C | F44: 0.176 | G44: 0.177 | P44: =IF(COUNT(F44:O44)=0, "", IF(OR(MIN(F44:O44) < (B44+C44), MAX(F44:O44) > (B44+D44)), "NG", "OK")) -> OK
A45: 32 | B45: 0.0875 | C45: -0.002 | D45: 0.002 | E45: C | F45: 0.0875 | P45: =IF(COUNT(F45:O45)=0, "", IF(OR(MIN(F45:O45) < (B45+C45), MAX(F45:O45) > (B45+D45)), "NG", "OK")) -> OK
A46: 33 | B46: 0.5875 | C46: -0.002 | D46: 0.002 | E46: C | F46: 0.5895 | P46: =IF(COUNT(F46:O46)=0, "", IF(OR(MIN(F46:O46) < (B46+C46), MAX(F46:O46) > (B46+D46)), "NG", "OK")) -> OK
A47: 34 | B47: 1.0875 | C47: -0.002 | D47: 0.002 | E47: C | F47: 1.0891 | P47: =IF(COUNT(F47:O47)=0, "", IF(OR(MIN(F47:O47) < (B47+C47), MAX(F47:O47) > (B47+D47)), "NG", "OK")) -> OK
A48: 35 | B48: 1.5875 | C48: -0.002 | D48: 0.002 | E48: C | F48: 1.5895 | P48: =IF(COUNT(F48:O48)=0, "", IF(OR(MIN(F48:O48) < (B48+C48), MAX(F48:O48) > (B48+D48)), "NG", "OK")) -> OK
A49: 36 | B49: 2.0875 | C49: -0.002 | D49: 0.002 | E49: C | F49: 2.089 | P49: =IF(COUNT(F49:O49)=0, "", IF(OR(MIN(F49:O49) < (B49+C49), MAX(F49:O49) > (B49+D49)), "NG", "OK")) -> OK
A50: 37 | B50: 2.5875 | C50: -0.002 | D50: 0.002 | E50: C | F50: 2.5892 | P50: =IF(COUNT(F50:O50)=0, "", IF(OR(MIN(F50:O50) < (B50+C50), MAX(F50:O50) > (B50+D50)), "NG", "OK")) -> OK
...

Sheet Inspection 41-42
A1: BÁO CÁO KIỂM TRA LINH KIỆN
A2: THE PARTS INSPECTION REPORT MMFDIF067.00 (16Jan2026)
K4: Date/Ngày kiểm tra: | N4: ='Inspection 1-40 (2)'!N4:O4 -> 12-MAR-2026
A5: Parts Name/Tên linh kiện: | C5: ='Inspection 1-40 (2)'!C5 -> 106C | D5: Mold Name/Tên khuôn: | G5: ='Inspection 1-40 (2)'!G5 -> MF00307 | K5: Department/Bộ phận: | N5: INJECTION
A6: Materia/Nguyên liệu: | C6: ='Inspection 1-40 (2)'!C6 -> HPM31 | F6: HRC : | G6: ='Inspection 1-40 (2)'!G6 -> 56-58 | K6: QTY/Số lượng: | N6: ='Inspection 1-40 (2)'!N6 -> 2
P7: JUDGEMENT
A8: A) Calipers B) Digital micrometer C) Microscope D) Comparator E) Pin gauge F) Micrometer | P8: =IF(COUNTIF(P14:P60, "NG")>0, "REJECTED", IF(COUNTIF(P14:P60, "OK")>0, "PASSED", "")) -> PASSED
A9: A) Thước cặp B) Thước đo điện tử C) Kính hiểm vi D) Bộ căn dưỡng E) Đồng hồ đo F) Panme
A11: Specification | F11: Sample No.
A12: Point/Điểm | B12: Nominal | C12: Tol/Dung sai | E12: Tool | F12: ='Inspection 1-40 (2)'!F12 -> 1 | G12: ='Inspection 1-40 (2)'!G12 -> 2 | H12: ='Inspection 1-40 (2)'!H12 -> 3 | I12: ='Inspection 1-40 (2)'!I12 -> 4 | J12: ='Inspection 1-40 (2)'!J12 -> 5 | K12: ='Inspection 1-40 (2)'!K12 -> 6 | L12: ='Inspection 1-40 (2)'!L12 -> 7 | M12: ='Inspection 1-40 (2)'!M12 -> 8 | ... O12: ='Inspection 1-40 (2)'!O12 -> 10 | P12: Remark/Ghi chú
C13: - | D13: + | F13: Detail/Chi tiết
A14: 41 | B14: 4.5875 | C14: -0.002 | D14: 0.002 | E14: C | F14: 4.5893 | G14: 4.5894 | P14: =IF(COUNT(F14:O14)=0, "", IF(OR(MIN(F14:O14) < (B14+C14), MAX(F14:O14) > (B14+D14)), "NG", "OK")) -> OK
A15: 42 | B15: 5 | C15: -0.1 | D15: 0.1 | E15: C | F15: 5.1 | P15: =IF(COUNT(F15:O15)=0, "", IF(OR(MIN(F15:O15) < (B15+C15), MAX(F15:O15) > (B15+D15)), "NG", "OK")) -> OK
P16: =IF(COUNT(F16:O16)=0, "", IF(OR(MIN(F16:O16) < (B16+C16), MAX(F16:O16) > (B16+D16)), "NG", "OK"))
P17: =IF(COUNT(F17:O17)=0, "", IF(OR(MIN(F17:O17) < (B17+C17), MAX(F17:O17) > (B17+D17)), "NG", "OK"))
P18: =IF(COUNT(F18:O18)=0, "", IF(OR(MIN(F18:O18) < (B18+C18), MAX(F18:O18) > (B18+D18)), "NG", "OK"))
P19: =IF(COUNT(F19:O19)=0, "", IF(OR(MIN(F19:O19) < (B19+C19), MAX(F19:O19) > (B19+D19)), "NG", "OK"))
P20: =IF(COUNT(F20:O20)=0, "", IF(OR(MIN(F20:O20) < (B20+C20), MAX(F20:O20) > (B20+D20)), "NG", "OK"))
P21: =IF(COUNT(F21:O21)=0, "", IF(OR(MIN(F21:O21) < (B21+C21), MAX(F21:O21) > (B21+D21)), "NG", "OK"))
P22: =IF(COUNT(F22:O22)=0, "", IF(OR(MIN(F22:O22) < (B22+C22), MAX(F22:O22) > (B22+D22)), "NG", "OK"))
P23: =IF(COUNT(F23:O23)=0, "", IF(OR(MIN(F23:O23) < (B23+C23), MAX(F23:O23) > (B23+D23)), "NG", "OK"))
P24: =IF(COUNT(F24:O24)=0, "", IF(OR(MIN(F24:O24) < (B24+C24), MAX(F24:O24) > (B24+D24)), "NG", "OK"))
P25: =IF(COUNT(F25:O25)=0, "", IF(OR(MIN(F25:O25) < (B25+C25), MAX(F25:O25) > (B25+D25)), "NG", "OK"))
P26: =IF(COUNT(F26:O26)=0, "", IF(OR(MIN(F26:O26) < (B26+C26), MAX(F26:O26) > (B26+D26)), "NG", "OK"))
P27: =IF(COUNT(F27:O27)=0, "", IF(OR(MIN(F27:O27) < (B27+C27), MAX(F27:O27) > (B27+D27)), "NG", "OK"))
... P53: =IF(COUNT(F53:O53)=0, "", IF(OR(MIN(F53:O53) < (B53+C53), MAX(F53:O53) > (B53+D53)), "NG", "OK"))
A54: Ngoại quan/ Appearance | F54: ='Inspection 1-40 (2)'!F54 -> OK | G54: ='Inspection 1-40 (2)'!G54 -> OK
A55: Lưu ý:
A56: -Tất cả linh kiện khi nhận về từ Nhà Cung Cấp bắt buộc phải được kiểm tra ngoại quan và kích thước như bản vẽ trước khi nhập kho .
A57: -All the mold part when receive in from Supplier must be checking appearance and dimensions before entering the warehouse stock .
C58: 7139 | F58: Confirm by Xác Nhận | L58: Approved by Phê Duyệt
